Workbook

Sheet Version History
A1: F5 Model v1.0
A2: v1.0
A3: Inputs: Starter xRA + Team offense vs hand
A4: Park factor: excluded
A5: Distribution: Poisson
A6: Win% derived from λ_home / λ_away

Sheet Dashboard
B1: =Bets!D1 -> 0 | C1: =Bets!E1 -> W | D1: =Bets!F1 -> L | E1: =Bets!G1 -> P | L1: =Bets!H1 -> Units P/L | M1: =Bets!I1 -> CLV | N1: =Bets!I1 -> CLV | P1: =Bets!J1 -> Edge | R1: =Bets!K1 -> Yield | S1: =Bets!L1 -> ROI | T1: Pinnacle | U1: =SUMIFS(Bets!$L$10:$L$979, Bets!$A$10:$A$979, T1, Bets!$B$10:$B$979,$B$3) -> 8.0814274 | X1: =Bets!M1 -> BTL | Z1: =Bets!N1 -> xBTL | AA1: =Bets!P1 -> Number of Bets | AB1: =Bets!R1 -> 334
B2: Total | C2: =C4+C3 -> 168 | D2: =D4+D3 -> 151 | E2: =E4+E3 -> 44 | L2: =L4+L3 -> 22.709303 | M2: =AVERAGE(M3:M4) -> 0.004531267 | P2: =AVERAGE(P3:P4) -> 0.10042535 | R2: =AVERAGE(R3:R4) -> 0.065339193 | T2: BOL | U2: =SUMIFS(Bets!$L$10:$L$979, Bets!$A$10:$A$979, T2, Bets!$B$10:$B$979,$B$3) -> 12.721985 | X2: =Bets!M2 -> 0.56298201 | Z2: =Bets!N2 -> 0.99673203 | AA2: =Bets!P2 -> Yield | AB2: =Bets!R2 -> 0.062133431
B3: =Bets!D3 -> 1st 5 ML | C3: =Bets!E3 -> 150 | D3: =Bets!F3 -> 140 | E3: =Bets!G3 -> 44 | L3: =Bets!H3 -> 20.721499 | M3: =Bets!I3 -> 0.010763363 | N3: =Bets!I3 -> 0.010763363 | P3: =Bets!J3 -> 0.1089083 | R3: =Bets!K3 -> 0.062133431 | S3: =Bets!L3 -> 0.20721499 | T3: BetMGM | U3: =SUMIFS(Bets!$L$10:$L$979, Bets!$A$10:$A$979, T3, Bets!$B$10:$B$979,$B$3) -> -2.8600335 | X3: =Bets!M3 -> 0.58682635 | Z3: =Bets!N3 -> 0.99638989 | AA3: =Bets!P3 -> Average Odds | AB3: =Bets!R3 -> 2.1795369
B4: =Bets!D4 -> 1st 5 RL | C4: =Bets!E4 -> 18 | D4: =Bets!F4 -> 11 | E4: =Bets!G4 -> 0 | L4: =Bets!H4 -> 1.9878037 | M4: =Bets!I4 -> -0.0017008293 | N4: . | P4: =Bets!J4 -> 0.091942412 | R4: =Bets!K4 -> 0.068544955 | S4: =Bets!L4 -> 0.019878037 | T4: BetRivers | U4: =SUMIFS(Bets!$L$10:$L$979, Bets!$A$10:$A$979, T4, Bets!$B$10:$B$979,$B$3) -> 3.9905015 | X4: =Bets!M4 -> 0.48275862 | AA4: =Bets!P4 -> Standard Deviation | AB4: =Bets!R4 -> 0.92814165
B5: Winrate | C5: =C3/(C3+D3) -> 0.51724138 | D5: =Bets!F5 -> 14 | E5: =Bets!G5 -> 3 | T5: DraftKings | U5: =SUMIFS(Bets!$L$10:$L$979, Bets!$A$10:$A$979, T5, Bets!$B$10:$B$979,$B$3) -> -2.1666667 | AA5: =Bets!P5 -> t-statistic | AB5: =Bets!R5 -> 1.2234446
B6: =Bets!D6 -> 0 | C6: =Bets!E6 -> 0 | D6: =Bets!F6 -> 0 | E6: ML | F6: RL | T6: FanDuel | U6: =SUMIFS(Bets!$L$10:$L$979, Bets!$A$10:$A$979, T6, Bets!$B$10:$B$979,$B$3) -> 0.95428571 | AA6: =Bets!P6 -> p-value | AB6: =Bets!R6 -> 0.22202684
B7: Date: | C7: =TODAY() -> 46109 | D7: Min Edge | E7: 1 | F7: 2 | T7: Sum | U7: =SUM(U1:U6) -> 20.721499 | AA7: =Bets!P7 -> 1-in-x probability | AB7: =Bets!R7 -> 4.50396
B8: Game Info | I8: My Projections | O8: Bookmaker | U8: Results | X8: Bets To Place | Y8: Bets To Place | Z8: Minimum Odds
B9: Game | C9: Teams | D9: Starting Pitcher | E9: Thr | F9: Pitcher Rank | G9: IP | H9: xR | I9: ML xW% | J9: ML Odds | K9: Sp +0.5 xW% | L9: Sp +0.5 Odds | M9: Sp -0.5 xW% | N9: Sp -0.5 Odds | O9: Book ML xW% | P9: ML Best Odds | Q9: Sp +0.5 xW% | R9: Sp +0.5 Odds | S9: Sp -0.5 xW% | T9: Sp -0.5 Odds | U9: ML Adj Kelly | V9: Sp Adj Kelly +0.5 | W9: Sp Adj Kelly -0.5 | X9: F5 Moneyline | Y9: F5 Spread | Z9: F5 Moneyline | AA9: F5 Spread +0.5 | AB9: F5 Spread -0.5
B10: 1 | C10: =IFERROR(_xlfn.XLOOKUP('First 5 Innings'!D5,Validations!$E$2:$E$31,Validations!$H$2:$H$31),"") -> Tampa Bay Rays | D10: =IFERROR('First 5 Innings'!B5,"") -> Joe Boyle | E10: ='First 5 Innings'!C5 -> R | F10: {=IFERROR(_xlfn.XLOOKUP(D10,'Starting Pitchers'!$B$4:$B1007,'Starting Pitchers'!$Z$4:$Z1007),"")} -> 153 | G10: {=IFERROR(_xlfn.XLOOKUP(D10,'Starting Pitchers'!$B$4:$B1007,'Starting Pitchers'!#REF!),"")} | H10: =IF('First 5 Innings'!G5=0,"",'First 5 Innings'!G5) -> 2.0592548 | I10: =IF(C10="","", 'First 5 Innings'!H5) -> 0.40830187 | J10: =IF(C10="","", _xlfn.LET( _xlpm.prob, 'First 5 Innings'!H5, _xlpm.dec, 1 / _xlpm.prob, IF(ABS(_xlpm.prob - 0.5) < 0.0001, 100, IF(_xlpm.dec >= 2, ROUND((_xlpm.dec - 1) * 100, 0), ROUND(-100 / (_xlpm.dec - 1), 0) ) ) )) -> 145 | K10: =IFERROR('First 5 Innings'!AH5,"") -> 0.49997682 | L10: =IFERROR( _xlfn.LET( _xlpm.prob, K10, _xlpm.dec, 1 / _xlpm.prob, IF(ABS(_xlpm.prob - 0.5) < 0.0001, 100, IF(_xlpm.dec >= 2, ROUND((_xlpm.dec - 1) * 100, 0), ROUND(-100 / (_xlpm.dec - 1), 0) ) ) ), "") -> 100 | M10: =IFERROR('First 5 Innings'!AI5,"") -> 0.31384222 | N10: =IFERROR(N7 _xlfn.LET( _xlpm.prob, M10, _xlpm.dec, 1 /_xlfn.SINGLE( _xlpm.prob), IF(ABS(_xlfn.SINGLE(_xlpm.prob) - 0.5) < 0.0001, 100, IF(_xlfn.SINGLE(_xlpm.dec) >= 2, ROUND((_xlfn.SINGLE(_xlpm.dec) - 1) * 100, 0), ROUND(-100 / (_xlfn.SINGLE(_xlpm.dec) - 1), 0) ) ) ), "") | O10: ='First 5 Innings'!S5 -> 0 | P10: =IFERROR( _xlfn.LET( _xlpm.prob, 'First 5 Innings'!S5, _xlpm.dec, 1 / _xlpm.prob, IF(ABS(_xlpm.prob - 0.5) < 0.0001, 100, IF(_xlpm.dec >= 2, ROUND((_xlpm.dec - 1) * 100, 0), ROUND(-100 / (_xlpm.dec - 1), 0) ) ) ), "") | Q10: =IFERROR(1/'First 5 Innings'!AD5,"") | R10: =IFERROR( _xludf.LET( prob, Q10, dec, 1 / prob, IF(ABS(prob - 0.5) < 0.0001, 100, IF(dec >= 2, ROUND((dec - 1) * 100, 0), ROUND(-100 / (dec - 1), 0) ) ) ), "") | S10: =IFERROR(1/'First 5 Innings'!AE5,"") | T10: =IFERROR( _xludf.LET( prob, S10, dec, 1 / prob, IF(ABS(prob - 0.5) < 0.0001, 100, IF(dec >= 2, ROUND((dec - 1) * 100, 0), ROUND(-100 / (dec - 1), 0) ) ) ), "") | U10: =IF(C10="","", 'First 5 Innings'!T5) -> 10 | V10: =IF(C10="","", 'First 5 Innings'!AJ5) -> 10 | W10: =IF(C10="","", 'First 5 Innings'!AK5) -> 10 | X10: =IF( OR(D10="Average", D10="", D11=""), "", IF(AND(U10 >= $E$7, U10 <= 9.99), C10 & " f5 " & ROUND(P10, 0) & " " & 'First 5 Innings'!Q5, "" ) ) | Y10: {=IF( OR(D10="Average", D10="", D11=""), "", _xludf.TEXTJOIN(CHAR(10), TRUE, IF(AND(V10 >= $F$7, V10 <= 9.99), _xludf.XLOOKUP('First 5 Innings'!D5, Validations!$E$2:$E$31, Validations!$H$2:$H$31) & " " & 'First 5 Innings'!$AJ$4 & " " & IF('First 5 Innings'!AD5 >= 2, ROUND(('First 5 Innings'!AD5 - 1) * 100, 0), ROUND(-100 / ('First 5 Innings'!AD5 - 1), 0) ) & " " & 'First 5 Innings'!AL5, "" ), IF(AND(W10 >= $F$7, W10 <= 9.99), _xludf.XLOOKUP('First 5 Innings'!D5, Validations!$E$2:$E$31, Validations!$H$2:$H$31) & " " & 'First 5 Innings'!$AK$4 & " " & IF('First 5 Innings'!AE5 >= 2, ROUND(('First 5 Innings'!AE5 - 1) * 100, 0), ROUND(-100 / ('First 5 Innings'!AE5 - 1), 0) ) & " " & 'First 5 Innings'!AM5, "" ) ) )} -> #NAME? | Z10: =IF('First 5 Innings'!W5<2, -100/('First 5 Innings'!W5-1), ('First 5 Innings'!W5-1)*100) -> 191.92168 | AA10: =IF('First 5 Innings'!AN5<2, -100/('First 5 Innings'!AN5-1), ('First 5 Innings'!AN5-1)*100) -> 100.01159 | AB10: =IF('First 5 Innings'!AO5<2, -100/('First 5 Innings'!AO5-1), ('First 5 Innings'!AO5-1)*100) -> 320.87105
C11: =IFERROR(_xlfn.XLOOKUP('First 5 Innings'!D6,Validations!$E$2:$E$31,Validations!$H$2:$H$31),"") -> St. Louis Cardinals | D11: =IFERROR('First 5 Innings'!B6,"") -> Michael McGreevy | E11: ='First 5 Innings'!C6 -> R | F11: {=IFERROR(_xlfn.XLOOKUP(D11,'Starting Pitchers'!$B$4:$B1007,'Starting Pitchers'!$Z$4:$Z1007),"")} -> 96 | G11: {=IFERROR(_xludf.XLOOKUP(D11,'Starting Pitchers'!$B$4:$B1007,'Starting Pitchers'!#REF!),"")} | H11: =IF('First 5 Innings'!G6=0,"",'First 5 Innings'!G6) -> 2.5805189 | I11: =IF(C11="","", 'First 5 Innings'!H6) -> 0.59169813 | J11: =IF(C11="","", _xlfn.LET( _xlpm.prob, 'First 5 Innings'!H6, _xlpm.dec, 1 / _xlpm.prob, IF(ABS(_xlpm.prob - 0.5) < 0.0001, 100, IF(_xlpm.dec >= 2, ROUND((_xlpm.dec - 1) * 100, 0), ROUND(-100 / (_xlpm.dec - 1), 0) ) ) )) -> -145 | K11: =IFERROR('First 5 Innings'!AH6,"") -> 0.68615778 | L11: =IFERROR( _xlfn.LET( _xlpm.prob, K11, _xlpm.dec, 1 / _xlpm.prob, IF(ABS(_xlpm.prob - 0.5) < 0.0001, 100, IF(_xlpm.dec >= 2, ROUND((_xlpm.dec - 1) * 100, 0), ROUND(-100 / (_xlpm.dec - 1), 0) ) ) ), "") -> -219 | M11: =IFERROR('First 5 Innings'!AI6,"") -> 0.50002318 | N11: =IFERROR( _xludf.LET( prob, M11, dec, 1 / prob, IF(ABS(prob - 0.5) < 0.0001, 100, IF(dec >= 2, ROUND((dec - 1) * 100, 0), ROUND(-100 / (dec - 1), 0) ) ) ), "") | O11: ='First 5 Innings'!S6 -> 0 | P11: =IFERROR( _xlfn.LET( _xlpm.prob, 'First 5 Innings'!S6, _xlpm.dec, 1 / _xlpm.prob, IF(ABS(_xlpm.prob - 0.5) < 0.0001, 100, IF(_xlpm.dec >= 2, ROUND((_xlpm.dec - 1) * 100, 0), ROUND(-100 / (_xlpm.dec - 1), 0) ) ) ), "") | Q11: =IFERROR(1/'First 5 Innings'!AD6,"") | R11: =IFERROR( _xludf.LET( prob, Q11, dec, 1 / prob, IF(ABS(prob - 0.5) < 0.0001, 100, IF(dec >= 2, ROUND((dec - 1) * 100, 0), ROUND(-100 / (dec - 1), 0) ) ) ), "") | S11: =IFERROR(1/'First 5 Innings'!AE6,"") | T11: =IFERROR( _xludf.LET( prob, S11, dec, 1 / prob, IF(ABS(prob - 0.5) < 0.0001, 100, IF(dec >= 2, ROUND((dec - 1) * 100, 0), ROUND(-100 / (dec - 1), 0) ) ) ), "") | U11: =IF(C11="","", 'First 5 Innings'!T6) -> 10 | V11: =IF(C11="","", 'First 5 Innings'!AJ6) -> 10 | W11: =IF(C11="","", 'First 5 Innings'!AK6) -> 10 | X11: =IF( OR(D11="Average", D11="", D12=""), "", IF(AND(U11 >= $E$7, U11 <= 9.99), C11 & " f5 " & ROUND(P11, 0) & " " & 'First 5 Innings'!Q6, "" ) ) | Y11: {=IF( OR(D11="Average", D11="", D12=""), "", _xludf.TEXTJOIN(CHAR(10), TRUE, IF(AND(V11 >= $F$7, V11 <= 9.99), _xludf.XLOOKUP('First 5 Innings'!D6, Validations!$E$2:$E$31, Validations!$H$2:$H$31) & " " & 'First 5 Innings'!$AJ$4 & " " & IF('First 5 Innings'!AD6 >= 2, ROUND(('First 5 Innings'!AD6 - 1) * 100, 0), ROUND(-100 / ('First 5 Innings'!AD6 - 1), 0) ) & " " & 'First 5 Innings'!AL6, "" ), IF(AND(W11 >= $F$7, W11 <= 9.99), _xludf.XLOOKUP('First 5 Innings'!D6, Validations!$E$2:$E$31, Validations!$H$2:$H$31) & " " & 'First 5 Innings'!$AK$4 & " " & IF('First 5 Innings'!AE6 >= 2, ROUND(('First 5 Innings'!AE6 - 1) * 100, 0), ROUND(-100 / ('First 5 Innings'!AE6 - 1), 0) ) & " " & 'First 5 Innings'!AM6, "" ) ) )} -> #NAME? | Z11: =IF('First 5 Innings'!W6<2, -100/('First 5 Innings'!W6-1), ('First 5 Innings'!W6-1)*100) -> -120.42515 | AA11: =IF('First 5 Innings'!AN6<2, -100/('First 5 Innings'!AN6-1), ('First 5 Innings'!AN6-1)*100) -> -274.1076 | AB11: =IF('First 5 Innings'!AO6<2, -100/('First 5 Innings'!AO6-1), ('First 5 Innings'!AO6-1)*100) -> 124.98696
B12: 2 | C12: =IFERROR(_xlfn.XLOOKUP('First 5 Innings'!D7,Validations!$E$2:$E$31,Validations!$H$2:$H$31),"") -> Washington Nationals | D12: =IFERROR('First 5 Innings'!B7,"") -> Miles Mikolas | E12: ='First 5 Innings'!C7 -> R | F12: {=IFERROR(_xlfn.XLOOKUP(D12,'Starting Pitchers'!$B$4:$B1007,'Starting Pitchers'!$Z$4:$Z1007),"")} -> 132 | G12: {=IFERROR(_xludf.XLOOKUP(D12,'Starting Pitchers'!$B$4:$B1007,'Starting Pitchers'!#REF!),"")} | H12: =IF('First 5 Innings'!G7=0,"",'First 5 Innings'!G7) -> 1.2815109 | I12: =IF(C12="","", 'First 5 Innings'!H7) -> 0.66310086 | J12: =IF(C12="","", _xlfn.LET( _xlpm.prob, 'First 5 Innings'!H7, _xlpm.dec, 1 / _xlpm.prob, IF(ABS(_xlpm.prob - 0.5) < 0.0001, 100, IF(_xlpm.dec >= 2, ROUND((_xlpm.dec - 1) * 100, 0), ROUND(-100 / (_xlpm.dec - 1), 0) ) ) )) -> -197 | K12: =IFERROR('First 5 Innings'!AH7,"") -> 0.7746757 | L12: =IFERROR( _xlfn.LET( _xlpm.prob, K12, _xlpm.dec, 1 / _xlpm.prob, IF(ABS(_xlpm.prob - 0.5) < 0.0001, 100, IF(_xlpm.dec >= 2, ROUND((_xlpm.dec - 1) * 100, 0), ROUND(-100 / (_xlpm.dec - 1), 0) ) ) ), "") -> -344 | M12: =IFERROR('First 5 Innings'!AI7,"") -> 0.48449763 | N12: =IFERROR( _xludf.LET( prob, M12, dec, 1 / prob, IF(ABS(prob - 0.5) < 0.0001, 100, IF(dec >= 2, ROUND((dec - 1) * 100, 0), ROUND(-100 / (dec - 1), 0) ) ) ), "") | O12: ='First 5 Innings'!S7 -> 0 | P12: =IFERROR( _xlfn.LET( _xlpm.prob, 'First 5 Innings'!S7, _xlpm.dec, 1 / _xlpm.prob, IF(ABS(_xlpm.prob - 0.5) < 0.0001, 100, IF(_xlpm.dec >= 2, ROUND((_xlpm.dec - 1) * 100, 0), ROUND(-100 / (_xlpm.dec - 1), 0) ) ) ), "") | Q12: =IFERROR(1/'First 5 Innings'!AD7,"") | R12: =IFERROR( _xludf.LET( prob, Q12, dec, 1 / prob, IF(ABS(prob - 0.5) < 0.0001, 100, IF(dec >= 2, ROUND((dec - 1) * 100, 0), ROUND(-100 / (dec - 1), 0) ) ) ), "") | S12: =IFERROR(1/'First 5 Innings'!AE7,"") | T12: =IFERROR( _xludf.LET( prob, S12, dec, 1 / prob, IF(ABS(prob - 0.5) < 0.0001, 100, IF(dec >= 2, ROUND((dec - 1) * 100, 0), ROUND(-100 / (dec - 1), 0) ) ) ), "") | U12: =IF(C12="","", 'First 5 Innings'!T7) -> 10 | V12: =IF(C12="","", 'First 5 Innings'!AJ7) -> 10 | W12: =IF(C12="","", 'First 5 Innings'!AK7) -> 10 | X12: =IF( OR(D12="Average", D12="", D13=""), "", IF(AND(U12 >= $E$7, U12 <= 9.99), C12 & " f5 " & ROUND(P12, 0) & " " & 'First 5 Innings'!Q7, "" ) ) | Y12: {=IF( OR(D12="Average", D12="", D13=""), "", _xludf.TEXTJOIN(CHAR(10), TRUE, IF(AND(V12 >= $F$7, V12 <= 9.99), _xludf.XLOOKUP('First 5 Innings'!D7, Validations!$E$2:$E$31, Validations!$H$2:$H$31) & " " & 'First 5 Innings'!$AJ$4 & " " & IF('First 5 Innings'!AD7 >= 2, ROUND(('First 5 Innings'!AD7 - 1) * 100, 0), ROUND(-100 / ('First 5 Innings'!AD7 - 1), 0) ) & " " & 'First 5 Innings'!AL7, "" ), IF(AND(W12 >= $F$7, W12 <= 9.99), _xludf.XLOOKUP('First 5 Innings'!D7, Validations!$E$2:$E$31, Validations!$H$2:$H$31) & " " & 'First 5 Innings'!$AK$4 & " " & IF('First 5 Innings'!AE7 >= 2, ROUND(('First 5 Innings'!AE7 - 1) * 100, 0), ROUND(-100 / ('First 5 Innings'!AE7 - 1), 0) ) & " " & 'First 5 Innings'!AM7, "" ) ) )} -> #NAME? | Z12: =IF('First 5 Innings'!W7<2, -100/('First 5 Innings'!W7-1), ('First 5 Innings'!W7-1)*100) -> -167.14226 | AA12: =IF('First 5 Innings'!AN7<2, -100/('First 5 Innings'!AN7-1), ('First 5 Innings'!AN7-1)*100) -> -538.3439 | AB12: =IF('First 5 Innings'!AO7<2, -100/('First 5 Innings'!AO7-1), ('First 5 Innings'!AO7-1)*100) -> 134.07166
C13: =IFERROR(_xlfn.XLOOKUP('First 5 Innings'!D8,Validations!$E$2:$E$31,Validations!$H$2:$H$31),"") -> Chicago Cubs | D13: =IFERROR('First 5 Innings'!B8,"") -> Cade Horton | E13: ='First 5 Innings'!C8 -> R | F13: {=IFERROR(_xlfn.XLOOKUP(D13,'Starting Pitchers'!$B$4:$B1007,'Starting Pitchers'!$Z$4:$Z1007),"")} -> 2 | G13: {=IFERROR(_xludf.XLOOKUP(D13,'Starting Pitchers'!$B$4:$B1007,'Starting Pitchers'!#REF!),"")} | H13: =IF('First 5 Innings'!G8=0,"",'First 5 Innings'!G8) -> 0.77474742 | I13: =IF(C13="","", 'First 5 Innings'!H8) -> 0.33689914 | J13: =IF(C13="","", _xlfn.LET( _xlpm.prob, 'First 5 Innings'!H8, _xlpm.dec, 1 / _xlpm.prob, IF(ABS(_xlpm.prob - 0.5) < 0.0001, 100, IF(_xlpm.dec >= 2, ROUND((_xlpm.dec - 1) * 100, 0), ROUND(-100 / (_xlpm.dec - 1), 0) ) ) )) -> 197 | K13: =IFERROR('First 5 Innings'!AH8,"") -> 0.51550237 | L13: =IFERROR( _xlfn.LET( _xlpm.prob, K13, _xlpm.dec, 1 / _xlpm.prob, IF(ABS(_xlpm.prob - 0.5) < 0.0001, 100, IF(_xlpm.dec >= 2, ROUND((_xlpm.dec - 1) * 100, 0), ROUND(-100 / (_xlpm.dec - 1), 0) ) ) ), "") -> -106 | M13: =IFERROR('First 5 Innings'!AI8,"") -> 0.2253243 | N13: =IFERROR( _xludf.LET( prob, M13, dec, 1 / prob, IF(ABS(prob - 0.5) < 0.0001, 100, IF(dec >= 2, ROUND((dec - 1) * 100, 0), ROUND(-100 / (dec - 1), 0) ) ) ), "") | O13: ='First 5 Innings'!S8 -> 0 | P13: =IFERROR( _xlfn.LET( _xlpm.prob, 'First 5 Innings'!S8, _xlpm.dec, 1 / _xlpm.prob, IF(ABS(_xlpm.prob - 0.5) < 0.0001, 100, IF(_xlpm.dec >= 2, ROUND((_xlpm.dec - 1) * 100, 0), ROUND(-100 / (_xlpm.dec - 1), 0) ) ) ), "") | Q13: =IFERROR(1/'First 5 Innings'!AD8,"") | R13: =IFERROR( _xludf.LET( prob, Q13, dec, 1 / prob, IF(ABS(prob - 0.5) < 0.0001, 100, IF(dec >= 2, ROUND((dec - 1) * 100, 0), ROUND(-100 / (dec - 1), 0) ) ) ), "") | S13: =IFERROR(1/'First 5 Innings'!AE8,"") | T13: =IFERROR( _xludf.LET( prob, S13, dec, 1 / prob, IF(ABS(prob - 0.5) < 0.0001, 100, IF(dec >= 2, ROUND((dec - 1) * 100, 0), ROUND(-100 / (dec - 1), 0) ) ) ), "") | U13: =IF(C13="","", 'First 5 Innings'!T8) -> 10 | V13: =IF(C13="","", 'First 5 Innings'!AJ8) -> 10 | W13: =IF(C13="","", 'First 5 Innings'!AK8) -> 10 | X13: =IF( OR(D13="Average", D13="", D14=""), "", IF(AND(U13 >= $E$7, U13 <= 9.99), C13 & " f5 " & ROUND(P13, 0) & " " & 'First 5 Innings'!Q8, "" ) ) | Y13: {=IF( OR(D13="Average", D13="", D14=""), "", _xludf.TEXTJOIN(CHAR(10), TRUE, IF(AND(V13 >= $F$7, V13 <= 9.99), _xludf.XLOOKUP('First 5 Innings'!D8, Validations!$E$2:$E$31, Validations!$H$2:$H$31) & " " & 'First 5 Innings'!$AJ$4 & " " & IF('First 5 Innings'!AD8 >= 2, ROUND(('First 5 Innings'!AD8 - 1) * 100, 0), ROUND(-100 / ('First 5 Innings'!AD8 - 1), 0) ) & " " & 'First 5 Innings'!AL8, "" ), IF(AND(W13 >= $F$7, W13 <= 9.99), _xludf.XLOOKUP('First 5 Innings'!D8, Validations!$E$2:$E$31, Validations!$H$2:$H$31) & " " & 'First 5 Innings'!$AK$4 & " " & IF('First 5 Innings'!AE8 >= 2, ROUND(('First 5 Innings'!AE8 - 1) * 100, 0), ROUND(-100 / ('First 5 Innings'!AE8 - 1), 0) ) & " " & 'First 5 Innings'!AM8, "" ) ) )} -> #NAME? | Z13: =IF('First 5 Innings'!W8<2, -100/('First 5 Innings'!W8-1), ('First 5 Innings'!W8-1)*100) -> 279.90851 | AA13: =IF('First 5 Innings'!AN8<2, -100/('First 5 Innings'!AN8-1), ('First 5 Innings'!AN8-1)*100) -> -108.0637 | AB13: =IF('First 5 Innings'!AO8<2, -100/('First 5 Innings'!AO8-1), ('First 5 Innings'!AO8-1)*100) -> 618.13689
B14: 3 | C14: =IFERROR(_xlfn.XLOOKUP('First 5 Innings'!D9,Validations!$E$2:$E$31,Validations!$H$2:$H$31),"") -> Oakland Athletics | D14: =IFERROR('First 5 Innings'!B9,"") -> Jeffrey Springs | E14: ='First 5 Innings'!C9 -> L | F14: {=IFERROR(_xlfn.XLOOKUP(D14,'Starting Pitchers'!$B$4:$B1007,'Starting Pitchers'!$Z$4:$Z1007),"")} -> 107 | G14: {=IFERROR(_xludf.XLOOKUP(D14,'Starting Pitchers'!$B$4:$B1007,'Starting Pitchers'!#REF!),"")} | H14: =IF('First 5 Innings'!G9=0,"",'First 5 Innings'!G9) -> 2.781908 | I14: =IF(C14="","", 'First 5 Innings'!H9) -> 0.5008202 | J14: =IF(C14="","", _xlfn.LET( _xlpm.prob, 'First 5 Innings'!H9, _xlpm.dec, 1 / _xlpm.prob, IF(ABS(_xlpm.prob - 0.5) < 0.0001, 100, IF(_xlpm.dec >= 2, ROUND((_xlpm.dec - 1) * 100, 0), ROUND(-100 / (_xlpm.dec - 1), 0) ) ) )) -> -100 | K14: =IFERROR('First 5 Innings'!AH9,"") -> 0.58763067 | L14: =IFERROR( _xlfn.LET( _xlpm.prob, K14, _xlpm.dec, 1 / _xlpm.prob, IF(ABS(_xlpm.prob - 0.5) < 0.0001, 100, IF(_xlpm.dec >= 2, ROUND((_xlpm.dec - 1) * 100, 0), ROUND(-100 / (_xlpm.dec - 1), 0) ) ) ), "") -> -143 | M14: =IFERROR('First 5 Innings'!AI9,"") -> 0.41412144 | N14: =IFERROR( _xludf.LET( prob, M14, dec, 1 / prob, IF(ABS(prob - 0.5) < 0.0001, 100, IF(dec >= 2, ROUND((dec - 1) * 100, 0), ROUND(-100 / (dec - 1), 0) ) ) ), "") | O14: ='First 5 Innings'!S9 -> 0 | P14: =IFERROR( _xlfn.LET( _xlpm.prob, 'First 5 Innings'!S9, _xlpm.dec, 1 / _xlpm.prob, IF(ABS(_xlpm.prob - 0.5) < 0.0001, 100, IF(_xlpm.dec >= 2, ROUND((_xlpm.dec - 1) * 100, 0), ROUND(-100 / (_xlpm.dec - 1), 0) ) ) ), "") | Q14: =IFERROR(1/'First 5 Innings'!AD9,"") | R14: =IFERROR( _xludf.LET( prob, Q14, dec, 1 / prob, IF(ABS(prob - 0.5) < 0.0001, 100, IF(dec >= 2, ROUND((dec - 1) * 100, 0), ROUND(-100 / (dec - 1), 0) ) ) ), "") | S14: =IFERROR(1/'First 5 Innings'!AE9,"") | T14: =IFERROR( _xludf.LET( prob, S14, dec, 1 / prob, IF(ABS(prob - 0.5) < 0.0001, 100, IF(dec >= 2, ROUND((dec - 1) * 100, 0), ROUND(-100 / (dec - 1), 0) ) ) ), "") | U14: =IF(C14="","", 'First 5 Innings'!T9) -> 10 | V14: =IF(C14="","", 'First 5 Innings'!AJ9) -> 10 | W14: =IF(C14="","", 'First 5 Innings'!AK9) -> 10 | X14: =IF( OR(D14="Average", D14="", D15=""), "", IF(AND(U14 >= $E$7, U14 <= 9.99), C14 & " f5 " & ROUND(P14, 0) & " " & 'First 5 Innings'!Q9, "" ) ) | Y14: {=IF( OR(D14="Average", D14="", D15=""), "", _xludf.TEXTJOIN(CHAR(10), TRUE, IF(AND(V14 >= $F$7, V14 <= 9.99), _xludf.XLOOKUP('First 5 Innings'!D9, Validations!$E$2:$E$31, Validations!$H$2:$H$31) & " " & 'First 5 Innings'!$AJ$4 & " " & IF('First 5 Innings'!AD9 >= 2, ROUND(('First 5 Innings'!AD9 - 1) * 100, 0), ROUND(-100 / ('First 5 Innings'!AD9 - 1), 0) ) & " " & 'First 5 Innings'!AL9, "" ), IF(AND(W14 >= $F$7, W14 <= 9.99), _xludf.XLOOKUP('First 5 Innings'!D9, Validations!$E$2:$E$31, Validations!$H$2:$H$31) & " " & 'First 5 Innings'!$AK$4 & " " & IF('First 5 Innings'!AE9 >= 2, ROUND(('First 5 Innings'!AE9 - 1) * 100, 0), ROUND(-100 / ('First 5 Innings'!AE9 - 1), 0) ) & " " & 'First 5 Innings'!AM9, "" ) ) )} -> #NAME? | Z14: =IF('First 5 Innings'!W9<2, -100/('First 5 Innings'!W9-1), ('First 5 Innings'!W9-1)*100) -> 124.53958 | AA14: =IF('First 5 Innings'!AN9<2, -100/('First 5 Innings'!AN9-1), ('First 5 Innings'!AN9-1)*100) -> -156.10709 | AB14: =IF('First 5 Innings'!AO9<2, -100/('First 5 Innings'!AO9-1), ('First 5 Innings'!AO9-1)*100) -> 186.5134
C15: =IFERROR(_xlfn.XLOOKUP('First 5 Innings'!D10,Validations!$E$2:$E$31,Validations!$H$2:$H$31),"") -> Toronto Blue Jays | D15: =IFERROR('First 5 Innings'!B10,"") -> Dylan Cease | E15: ='First 5 Innings'!C10 -> R | F15: {=IFERROR(_xlfn.XLOOKUP(D15,'Starting Pitchers'!$B$4:$B1007,'Starting Pitchers'!$Z$4:$Z1007),"")} -> 85 | G15: {=IFERROR(_xludf.XLOOKUP(D15,'Starting Pitchers'!$B$4:$B1007,'Starting Pitchers'!#REF!),"")} | H15: =IF('First 5 Innings'!G10=0,"",'First 5 Innings'!G10) -> 2.7766069 | I15: =IF(C15="","", 'First 5 Innings'!H10) -> 0.4991798 | J15: =IF(C15="","", _xlfn.LET( _xlpm.prob, 'First 5 Innings'!H10, _xlpm.dec, 1 / _xlpm.prob, IF(ABS(_xlpm.prob - 0.5) < 0.0001, 100, IF(_xlpm.dec >= 2, ROUND((_xlpm.dec - 1) * 100, 0), ROUND(-100 / (_xlpm.dec - 1), 0) ) ) )) -> 100 | K15: =IFERROR('First 5 Innings'!AH10,"") -> 0.58587856 | L15: =IFERROR( _xlfn.LET( _xlpm.prob, K15, _xlpm.dec, 1 / _xlpm.prob, IF(ABS(_xlpm.prob - 0.5) < 0.0001, 100, IF(_xlpm.dec >= 2, ROUND((_xlpm.dec - 1) * 100, 0), ROUND(-100 / (_xlpm.dec - 1), 0) ) ) ), "") -> -141 | M15: =IFERROR('First 5 Innings'!AI10,"") -> 0.41236933 | N15: =IFERROR( _xludf.LET( prob, M15, dec, 1 / prob, IF(ABS(prob - 0.5) < 0.0001, 100, IF(dec >= 2, ROUND((dec - 1) * 100, 0), ROUND(-100 / (dec - 1), 0) ) ) ), "") | O15: ='First 5 Innings'!S10 -> 0 | P15: =IFERROR( _xlfn.LET( _xlpm.prob, 'First 5 Innings'!S10, _xlpm.dec, 1 / _xlpm.prob, IF(ABS(_xlpm.prob - 0.5) < 0.0001, 100, IF(_xlpm.dec >= 2, ROUND((_xlpm.dec - 1) * 100, 0), ROUND(-100 / (_xlpm.dec - 1), 0) ) ) ), "") | Q15: =IFERROR(1/'First 5 Innings'!AD10,"") | R15: =IFERROR( _xludf.LET( prob, Q15, dec, 1 / prob, IF(ABS(prob - 0.5) < 0.0001, 100, IF(dec >= 2, ROUND((dec - 1) * 100, 0), ROUND(-100 / (dec - 1), 0) ) ) ), "") | S15: =IFERROR(1/'First 5 Innings'!AE10,"") | T15: =IFERROR( _xludf.LET( prob, S15, dec, 1 / prob, IF(ABS(prob - 0.5) < 0.0001, 100, IF(dec >= 2, ROUND((dec - 1) * 100, 0), ROUND(-100 / (dec - 1), 0) ) ) ), "") | U15: =IF(C15="","", 'First 5 Innings'!T10) -> 10 | V15: =IF(C15="","", 'First 5 Innings'!AJ10) -> 10 | W15: =IF(C15="","", 'First 5 Innings'!AK10) -> 10 | X15: =IF( OR(D15="Average", D15="", D16=""), "", IF(AND(U15 >= $E$7, U15 <= 9.99), C15 & " f5 " & ROUND(P15, 0) & " " & 'First 5 Innings'!Q10, "" ) ) | Y15: {=IF( OR(D15="Average", D15="", D16=""), "", _xludf.TEXTJOIN(CHAR(10), TRUE, IF(AND(V15 >= $F$7, V15 <= 9.99), _xludf.XLOOKUP('First 5 Innings'!D10, Validations!$E$2:$E$31, Validations!$H$2:$H$31) & " " & 'First 5 Innings'!$AJ$4 & " " & IF('First 5 Innings'!AD10 >= 2, ROUND(('First 5 Innings'!AD10 - 1) * 100, 0), ROUND(-100 / ('First 5 Innings'!AD10 - 1), 0) ) & " " & 'First 5 Innings'!AL10, "" ), IF(AND(W15 >= $F$7, W15 <= 9.99), _xludf.XLOOKUP('First 5 Innings'!D10, Validations!$E$2:$E$31, Validations!$H$2:$H$31) & " " & 'First 5 Innings'!$AK$4 & " " & IF('First 5 Innings'!AE10 >= 2, ROUND(('First 5 Innings'!AE10 - 1) * 100, 0), ROUND(-100 / ('First 5 Innings'!AE10 - 1), 0) ) & " " & 'First 5 Innings'!AM10, "" ) ) )} -> #NAME? | Z15: =IF('First 5 Innings'!W10<2, -100/('First 5 Innings'!W10-1), ('First 5 Innings'!W10-1)*100) -> 125.46231 | AA15: =IF('First 5 Innings'!AN10<2, -100/('First 5 Innings'!AN10-1), ('First 5 Innings'!AN10-1)*100) -> -154.67857 | AB15: =IF('First 5 Innings'!AO10<2, -100/('First 5 Innings'!AO10-1), ('First 5 Innings'!AO10-1)*100) -> 188.12048
B16: 4 | C16: =IFERROR(_xlfn.XLOOKUP('First 5 Innings'!D11,Validations!$E$2:$E$31,Validations!$H$2:$H$31),"") -> Minnesota Twins | D16: =IFERROR('First 5 Innings'!B11,"") -> Taj Bradley | E16: ='First 5 Innings'!C11 -> R | F16: {=IFERROR(_xlfn.XLOOKUP(D16,'Starting Pitchers'!$B$4:$B1007,'Starting Pitchers'!$Z$4:$Z1007),"")} -> 127 | G16: {=IFERROR(_xludf.XLOOKUP(D16,'Starting Pitchers'!$B$4:$B1007,'Starting Pitchers'!#REF!),"")} | H16: =IF('First 5 Innings'!G11=0,"",'First 5 Innings'!G11) -> 1.8266421 | I16: =IF(C16="","", 'First 5 Innings'!H11) -> 0.66486563 | J16: =IF(C16="","", _xlfn.LET( _xlpm.prob, 'First 5 Innings'!H11, _xlpm.dec, 1 / _xlpm.prob, IF(ABS(_xlpm.prob - 0.5) < 0.0001, 100, IF(_xlpm.dec >= 2, ROUND((_xlpm.dec - 1) * 100, 0), ROUND(-100 / (_xlpm.dec - 1), 0) ) ) )) -> -198 | K16: =IFERROR('First 5 Innings'!AH11,"") -> 0.76239149 | L16: =IFERROR( _xlfn.LET( _xlpm.prob, K16, _xlpm.dec, 1 / _xlpm.prob, IF(ABS(_xlpm.prob - 0.5) < 0.0001, 100, IF(_xlpm.dec >= 2, ROUND((_xlpm.dec - 1) * 100, 0), ROUND(-100 / (_xlpm.dec - 1), 0) ) ) ), "") -> -321 | M16: =IFERROR('First 5 Innings'!AI11,"") -> 0.53316404 | N16: =IFERROR( _xludf.LET( prob, M16, dec, 1 / prob, IF(ABS(prob - 0.5) < 0.0001, 100, IF(dec >= 2, ROUND((dec - 1) * 100, 0), ROUND(-100 / (dec - 1), 0) ) ) ), "") | O16: ='First 5 Innings'!S11 -> 0 | P16: =IFERROR( _xlfn.LET( _xlpm.prob, 'First 5 Innings'!S11, _xlpm.dec, 1 / _xlpm.prob, IF(ABS(_xlpm.prob - 0.5) < 0.0001, 100, IF(_xlpm.dec >= 2, ROUND((_xlpm.dec - 1) * 100, 0), ROUND(-100 / (_xlpm.dec - 1), 0) ) ) ), "") | Q16: =IFERROR(1/'First 5 Innings'!AD11,"") | R16: =IFERROR( _xludf.LET( prob, Q16, dec, 1 / prob, IF(ABS(prob - 0.5) < 0.0001, 100, IF(dec >= 2, ROUND((dec - 1) * 100, 0), ROUND(-100 / (dec - 1), 0) ) ) ), "") | S16: =IFERROR(1/'First 5 Innings'!AE11,"") | T16: =IFERROR( _xludf.LET( prob, S16, dec, 1 / prob, IF(ABS(prob - 0.5) < 0.0001, 100, IF(dec >= 2, ROUND((dec - 1) * 100, 0), ROUND(-100 / (dec - 1), 0) ) ) ), "") | U16: =IF(C16="","", 'First 5 Innings'!T11) -> 10 | V16: =IF(C16="","", 'First 5 Innings'!AJ11) -> 10 | W16: =IF(C16="","", 'First 5 Innings'!AK11) -> 10 | X16: =IF( OR(D16="Average", D16="", D17=""), "", IF(AND(U16 >= $E$7, U16 <= 9.99), C16 & " f5 " & ROUND(P16, 0) & " " & 'First 5 Innings'!Q11, "" ) ) | Y16: {=IF( OR(D16="Average", D16="", D17=""), "", _xludf.TEXTJOIN(CHAR(10), TRUE, IF(AND(V16 >= $F$7, V16 <= 9.99), _xludf.XLOOKUP('First 5 Innings'!D11, Validations!$E$2:$E$31, Validations!$H$2:$H$31) & " " & 'First 5 Innings'!$AJ$4 & " " & IF('First 5 Innings'!AD11 >= 2, ROUND(('First 5 Innings'!AD11 - 1) * 100, 0), ROUND(-100 / ('First 5 Innings'!AD11 - 1), 0) ) & " " & 'First 5 Innings'!AL11, "" ), IF(AND(W16 >= $F$7, W16 <= 9.99), _xludf.XLOOKUP('First 5 Innings'!D11, Validations!$E$2:$E$31, Validations!$H$2:$H$31) & " " & 'First 5 Innings'!$AK$4 & " " & IF('First 5 Innings'!AE11 >= 2, ROUND(('First 5 Innings'!AE11 - 1) * 100, 0), ROUND(-100 / ('First 5 Innings'!AE11 - 1), 0) ) & " " & 'First 5 Innings'!AM11, "" ) ) )} -> #NAME? | Z16: =IF('First 5 Innings'!W11<2, -100/('First 5 Innings'!W11-1), ('First 5 Innings'!W11-1)*100) -> -168.549 | AA16: =IF('First 5 Innings'!AN11<2, -100/('First 5 Innings'!AN11-1), ('First 5 Innings'!AN11-1)*100) -> -481.35941 | AB16: =IF('First 5 Innings'!AO11<2, -100/('First 5 Innings'!AO11-1), ('First 5 Innings'!AO11-1)*100) -> 107.77348
C17: =IFERROR(_xlfn.XLOOKUP('First 5 Innings'!D12,Validations!$E$2:$E$31,Validations!$H$2:$H$31),"") -> Baltimore Orioles | D17: =IFERROR('First 5 Innings'!B12,"") -> Kyle Bradish | E17: ='First 5 Innings'!C12 -> R | F17: {=IFERROR(_xlfn.XLOOKUP(D17,'Starting Pitchers'!$B$4:$B1007,'Starting Pitchers'!$Z$4:$Z1007),"")} -> 39 | G17: {=IFERROR(_xludf.XLOOKUP(D17,'Starting Pitchers'!$B$4:$B1007,'Starting Pitchers'!#REF!),"")} | H17: =IF('First 5 Innings'!G12=0,"",'First 5 Innings'!G12) -> 1.1452265 | I17: =IF(C17="","", 'First 5 Innings'!H12) -> 0.33513437 | J17: =IF(C17="","", _xlfn.LET( _xlpm.prob, 'First 5 Innings'!H12, _xlpm.dec, 1 / _xlpm.prob, IF(ABS(_xlpm.prob - 0.5) < 0.0001, 100, IF(_xlpm.dec >= 2, ROUND((_xlpm.dec - 1) * 100, 0), ROUND(-100 / (_xlpm.dec - 1), 0) ) ) )) -> 198 | K17: =IFERROR('First 5 Innings'!AH12,"") -> 0.46683596 | L17: =IFERROR( _xlfn.LET( _xlpm.prob, K17, _xlpm.dec, 1 / _xlpm.prob, IF(ABS(_xlpm.prob - 0.5) < 0.0001, 100, IF(_xlpm.dec >= 2, ROUND((_xlpm.dec - 1) * 100, 0), ROUND(-100 / (_xlpm.dec - 1), 0) ) ) ), "") -> 114 | M17: =IFERROR('First 5 Innings'!AI12,"") -> 0.23760851 | N17: =IFERROR( _xludf.LET( prob, M17, dec, 1 / prob, IF(ABS(prob - 0.5) < 0.0001, 100, IF(dec >= 2, ROUND((dec - 1) * 100, 0), ROUND(-100 / (dec - 1), 0) ) ) ), "") | O17: ='First 5 Innings'!S12 -> 0 | P17: =IFERROR( _xlfn.LET( _xlpm.prob, 'First 5 Innings'!S12, _xlpm.dec, 1 / _xlpm.prob, IF(ABS(_xlpm.prob - 0.5) < 0.0001, 100, IF(_xlpm.dec >= 2, ROUND((_xlpm.dec - 1) * 100, 0), ROUND(-100 / (_xlpm.dec - 1), 0) ) ) ), "") | Q17: =IFERROR(1/'First 5 Innings'!AD12,"") | R17: =IFERROR( _xludf.LET( prob, Q17, dec, 1 / prob, IF(ABS(prob - 0.5) < 0.0001, 100, IF(dec >= 2, ROUND((dec - 1) * 100, 0), ROUND(-100 / (dec - 1), 0) ) ) ), "") | S17: =IFERROR(1/'First 5 Innings'!AE12,"") | T17: =IFERROR( _xludf.LET( prob, S17, dec, 1 / prob, IF(ABS(prob - 0.5) < 0.0001, 100, IF(dec >= 2, ROUND((dec - 1) * 100, 0), ROUND(-100 / (dec - 1), 0) ) ) ), "") | U17: =IF(C17="","", 'First 5 Innings'!T12) -> 10 | V17: =IF(C17="","", 'First 5 Innings'!AJ12) -> 10 | W17: =IF(C17="","", 'First 5 Innings'!AK12) -> 10 | X17: =IF( OR(D17="Average", D17="", D18=""), "", IF(AND(U17 >= $E$7, U17 <= 9.99), C17 & " f5 " & ROUND(P17, 0) & " " & 'First 5 Innings'!Q12, "" ) ) | Y17: {=IF( OR(D17="Average", D17="", D18=""), "", _xludf.TEXTJOIN(CHAR(10), TRUE, IF(AND(V17 >= $F$7, V17 <= 9.99), _xludf.XLOOKUP('First 5 Innings'!D12, Validations!$E$2:$E$31, Validations!$H$2:$H$31) & " " & 'First 5 Innings'!$AJ$4 & " " & IF('First 5 Innings'!AD12 >= 2, ROUND(('First 5 Innings'!AD12 - 1) * 100, 0), ROUND(-100 / ('First 5 Innings'!AD12 - 1), 0) ) & " " & 'First 5 Innings'!AL12, "" ), IF(AND(W17 >= $F$7, W17 <= 9.99), _xludf.XLOOKUP('First 5 Innings'!D12, Validations!$E$2:$E$31, Validations!$H$2:$H$31) & " " & 'First 5 Innings'!$AK$4 & " " & IF('First 5 Innings'!AE12 >= 2, ROUND(('First 5 Innings'!AE12 - 1) * 100, 0), ROUND(-100 / ('First 5 Innings'!AE12 - 1), 0) ) & " " & 'First 5 Innings'!AM12, "" ) ) )} -> #NAME? | Z17: =IF('First 5 Innings'!W12<2, -100/('First 5 Innings'!W12-1), ('First 5 Innings'!W12-1)*100) -> 282.75986 | AA17: =IF('First 5 Innings'!AN12<2, -100/('First 5 Innings'!AN12-1), ('First 5 Innings'!AN12-1)*100) -> 118.08113 | AB17: =IF('First 5 Innings'!AO12<2, -100/('First 5 Innings'!AO12-1), ('First 5 Innings'!AO12-1)*100) -> 554.02933
B18: 5 | C18: =IFERROR(_xlfn.XLOOKUP('First 5 Innings'!D13,Validations!$E$2:$E$31,Validations!$H$2:$H$31),"") -> Texas Rangers | D18: =IFERROR('First 5 Innings'!B13,"") -> Jacob deGrom | E18: ='First 5 Innings'!C13 -> R | F18: {=IFERROR(_xlfn.XLOOKUP(D18,'Starting Pitchers'!$B$4:$B1007,'Starting Pitchers'!$Z$4:$Z1007),"")} -> 48 | G18: {=IFERROR(_xludf.XLOOKUP(D18,'Starting Pitchers'!$B$4:$B1007,'Starting Pitchers'!#REF!),"")} | H18: =IF('First 5 Innings'!G13=0,"",'First 5 Innings'!G13) -> 1.5453819 | I18: =IF(C18="","", 'First 5 Innings'!H13) -> 0.19615725 | J18: =IF(C18="","", _xlfn.LET( _xlpm.prob, 'First 5 Innings'!H13, _xlpm.dec, 1 / _xlpm.prob, IF(ABS(_xlpm.prob - 0.5) < 0.0001, 100, IF(_xlpm.dec >= 2, ROUND((_xlpm.dec - 1) * 100, 0), ROUND(-100 / (_xlpm.dec - 1), 0) ) ) )) -> 410 | K18: =IFERROR('First 5 Innings'!AH13,"") -> 0.24754946 | L18: =IFERROR( _xlfn.LET( _xlpm.prob, K18, _xlpm.dec, 1 / _xlpm.prob, IF(ABS(_xlpm.prob - 0.5) < 0.0001, 100, IF(_xlpm.dec >= 2, ROUND((_xlpm.dec - 1) * 100, 0), ROUND(-100 / (_xlpm.dec - 1), 0) ) ) ), "") -> 304 | M18: =IFERROR('First 5 Innings'!AI13,"") -> 0.12337603 | N18: =IFERROR( _xludf.LET( prob, M18, dec, 1 / prob, IF(ABS(prob - 0.5) < 0.0001, 100, IF(dec >= 2, ROUND((dec - 1) * 100, 0), ROUND(-100 / (dec - 1), 0) ) ) ), "") | O18: ='First 5 Innings'!S13 -> 0 | P18: =IFERROR( _xlfn.LET( _xlpm.prob, 'First 5 Innings'!S13, _xlpm.dec, 1 / _xlpm.prob, IF(ABS(_xlpm.prob - 0.5) < 0.0001, 100, IF(_xlpm.dec >= 2, ROUND((_xlpm.dec - 1) * 100, 0), ROUND(-100 / (_xlpm.dec - 1), 0) ) ) ), "") | Q18: =IFERROR(1/'First 5 Innings'!AD13,"") | R18: =IFERROR( _xludf.LET( prob, Q18, dec, 1 / prob, IF(ABS(prob - 0.5) < 0.0001, 100, IF(dec >= 2, ROUND((dec - 1) * 100, 0), ROUND(-100 / (dec - 1), 0) ) ) ), "") | S18: =IFERROR(1/'First 5 Innings'!AE13,"") | T18: =IFERROR( _xludf.LET( prob, S18, dec, 1 / prob, IF(ABS(prob - 0.5) < 0.0001, 100, IF(dec >= 2, ROUND((dec - 1) * 100, 0), ROUND(-100 / (dec - 1), 0) ) ) ), "") | U18: =IF(C18="","", 'First 5 Innings'!T13) -> 10 | V18: =IF(C18="","", 'First 5 Innings'!AJ13) -> 10 | W18: =IF(C18="","", 'First 5 Innings'!AK13) -> 10 | X18: =IF( OR(D18="Average", D18="", D19=""), "", IF(AND(U18 >= $E$7, U18 <= 9.99), C18 & " f5 " & ROUND(P18, 0) & " " & 'First 5 Innings'!Q13, "" ) ) | Y18: {=IF( OR(D18="Average", D18="", D19=""), "", _xludf.TEXTJOIN(CHAR(10), TRUE, IF(AND(V18 >= $F$7, V18 <= 9.99), _xludf.XLOOKUP('First 5 Innings'!D13, Validations!$E$2:$E$31, Validations!$H$2:$H$31) & " " & 'First 5 Innings'!$AJ$4 & " " & IF('First 5 Innings'!AD13 >= 2, ROUND(('First 5 Innings'!AD13 - 1) * 100, 0), ROUND(-100 / ('First 5 Innings'!AD13 - 1), 0) ) & " " & 'First 5 Innings'!AL13, "" ), IF(AND(W18 >= $F$7, W18 <= 9.99), _xludf.XLOOKUP('First 5 Innings'!D13, Validations!$E$2:$E$31, Validations!$H$2:$H$31) & " " & 'First 5 Innings'!$AK$4 & " " & IF('First 5 Innings'!AE13 >= 2, ROUND(('First 5 Innings'!AE13 - 1) * 100, 0), ROUND(-100 / ('First 5 Innings'!AE13 - 1), 0) ) & " " & 'First 5 Innings'!AM13, "" ) ) )} -> #NAME? | Z18: =IF('First 5 Innings'!W13<2, -100/('First 5 Innings'!W13-1), ('First 5 Innings'!W13-1)*100) -> 835.96688 | AA18: =IF('First 5 Innings'!AN13<2, -100/('First 5 Innings'!AN13-1), ('First 5 Innings'!AN13-1)*100) -> 442.19106 | AB18: =IF('First 5 Innings'!AO13<2, -100/('First 5 Innings'!AO13-1), ('First 5 Innings'!AO13-1)*100) -> 3750.0978
C19: =IFERROR(_xlfn.XLOOKUP('First 5 Innings'!D14,Validations!$E$2:$E$31,Validations!$H$2:$H$31),"") -> Philadelphia Phillies | D19: =IFERROR('First 5 Innings'!B14,"") -> Aaron Nola | E19: ='First 5 Innings'!C14 -> R | F19: {=IFERROR(_xlfn.XLOOKUP(D19,'Starting Pitchers'!$B$4:$B1007,'Starting Pitchers'!$Z$4:$Z1007),"")} -> 74 | G19: {=IFERROR(_xludf.XLOOKUP(D19,'Starting Pitchers'!$B$4:$B1007,'Starting Pitchers'!#REF!),"")} | H19: =IF('First 5 Innings'!G14=0,"",'First 5 Innings'!G14) -> 3.5853096 | I19: =IF(C19="","", 'First 5 Innings'!H14) -> 0.80384275 | J19: =IF(C19="","", _xlfn.LET( _xlpm.prob, 'First 5 Innings'!H14, _xlpm.dec, 1 / _xlpm.prob, IF(ABS(_xlpm.prob - 0.5) < 0.0001, 100, IF(_xlpm.dec >= 2, ROUND((_xlpm.dec - 1) * 100, 0), ROUND(-100 / (_xlpm.dec - 1), 0) ) ) )) -> -410 | K19: =IFERROR('First 5 Innings'!AH14,"") -> 0.87662397 | L19: =IFERROR( _xlfn.LET( _xlpm.prob, K19, _xlpm.dec, 1 / _xlpm.prob, IF(ABS(_xlpm.prob - 0.5) < 0.0001, 100, IF(_xlpm.dec >= 2, ROUND((_xlpm.dec - 1) * 100, 0), ROUND(-100 / (_xlpm.dec - 1), 0) ) ) ), "") -> -711 | M19: =IFERROR('First 5 Innings'!AI14,"") -> 0.75245054 | N19: =IFERROR( _xludf.LET( prob, M19, dec, 1 / prob, IF(ABS(prob - 0.5) < 0.0001, 100, IF(dec >= 2, ROUND((dec - 1) * 100, 0), ROUND(-100 / (dec - 1), 0) ) ) ), "") | O19: ='First 5 Innings'!S14 -> 0 | P19: =IFERROR( _xlfn.LET( _xlpm.prob, 'First 5 Innings'!S14, _xlpm.dec, 1 / _xlpm.prob, IF(ABS(_xlpm.prob - 0.5) < 0.0001, 100, IF(_xlpm.dec >= 2, ROUND((_xlpm.dec - 1) * 100, 0), ROUND(-100 / (_xlpm.dec - 1), 0) ) ) ), "") | Q19: =IFERROR(1/'First 5 Innings'!AD14,"") | R19: =IFERROR( _xludf.LET( prob, Q19, dec, 1 / prob, IF(ABS(prob - 0.5) < 0.0001, 100, IF(dec >= 2, ROUND((dec - 1) * 100, 0), ROUND(-100 / (dec - 1), 0) ) ) ), "") | S19: =IFERROR(1/'First 5 Innings'!AE14,"") | T19: =IFERROR( _xludf.LET( prob, S19, dec, 1 / prob, IF(ABS(prob - 0.5) < 0.0001, 100, IF(dec >= 2, ROUND((dec - 1) * 100, 0), ROUND(-100 / (dec - 1), 0) ) ) ), "") | U19: =IF(C19="","", 'First 5 Innings'!T14) -> 10 | V19: =IF(C19="","", 'First 5 Innings'!AJ14) -> 10 | W19: =IF(C19="","", 'First 5 Innings'!AK14) -> 10 | X19: =IF( OR(D19="Average", D19="", D20=""), "", IF(AND(U19 >= $E$7, U19 <= 9.99), C19 & " f5 " & ROUND(P19, 0) & " " & 'First 5 Innings'!Q14, "" ) ) | Y19: {=IF( OR(D19="Average", D19="", D20=""), "", _xludf.TEXTJOIN(CHAR(10), TRUE, IF(AND(V19 >= $F$7, V19 <= 9.99), _xludf.XLOOKUP('First 5 Innings'!D14, Validations!$E$2:$E$31, Validations!$H$2:$H$31) & " " & 'First 5 Innings'!$AJ$4 & " " & IF('First 5 Innings'!AD14 >= 2, ROUND(('First 5 Innings'!AD14 - 1) * 100, 0), ROUND(-100 / ('First 5 Innings'!AD14 - 1), 0) ) & " " & 'First 5 Innings'!AL14, "" ), IF(AND(W19 >= $F$7, W19 <= 9.99), _xludf.XLOOKUP('First 5 Innings'!D14, Validations!$E$2:$E$31, Validations!$H$2:$H$31) & " " & 'First 5 Innings'!$AK$4 & " " & IF('First 5 Innings'!AE14 >= 2, ROUND(('First 5 Innings'!AE14 - 1) * 100, 0), ROUND(-100 / ('First 5 Innings'!AE14 - 1), 0) ) & " " & 'First 5 Innings'!AM14, "" ) ) )} -> #NAME? | Z19: =IF('First 5 Innings'!W14<2, -100/('First 5 Innings'!W14-1), ('First 5 Innings'!W14-1)*100) -> -358.81557 | AA19: =IF('First 5 Innings'!AN14<2, -100/('First 5 Innings'!AN14-1), ('First 5 Innings'!AN14-1)*100) -> -3322.3091 | AB19: =IF('First 5 Innings'!AO14<2, -100/('First 5 Innings'!AO14-1), ('First 5 Innings'!AO14-1)*100) -> -263.5637
B20: 6 | C20: =IFERROR(_xlfn.XLOOKUP('First 5 Innings'!D15,Validations!$E$2:$E$31,Validations!$H$2:$H$31),"") -> Boston Red Sox | D20: =IFERROR('First 5 Innings'!B15,"") -> Sonny Gray | E20: ='First 5 Innings'!C15 -> R | F20: {=IFERROR(_xlfn.XLOOKUP(D20,'Starting Pitchers'!$B$4:$B1007,'Starting Pitchers'!$Z$4:$Z1007),"")} -> 102 | G20: {=IFERROR(_xludf.XLOOKUP(D20,'Starting Pitchers'!$B$4:$B1007,'Starting Pitchers'!#REF!),"")} | H20: =IF('First 5 Innings'!G15=0,"",'First 5 Innings'!G15) -> 2.7907438 | I20: =IF(C20="","", 'First 5 Innings'!H15) -> 0.61492647 | J20: =IF(C20="","", _xlfn.LET( _xlpm.prob, 'First 5 Innings'!H15, _xlpm.dec, 1 / _xlpm.prob, IF(ABS(_xlpm.prob - 0.5) < 0.0001, 100, IF(_xlpm.dec >= 2, ROUND((_xlpm.dec - 1) * 100, 0), ROUND(-100 / (_xlpm.dec - 1), 0) ) ) )) -> -160 | K20: =IFERROR('First 5 Innings'!AH15,"") -> 0.70730949 | L20: =IFERROR( _xlfn.LET( _xlpm.prob, K20, _xlpm.dec, 1 / _xlpm.prob, IF(ABS(_xlpm.prob - 0.5) < 0.0001, 100, IF(_xlpm.dec >= 2, ROUND((_xlpm.dec - 1) * 100, 0), ROUND(-100 / (_xlpm.dec - 1), 0) ) ) ), "") -> -242 | M20: =IFERROR('First 5 Innings'!AI15,"") -> 0.52949075 | N20: =IFERROR( _xludf.LET( prob, M20, dec, 1 / prob, IF(ABS(prob - 0.5) < 0.0001, 100, IF(dec >= 2, ROUND((dec - 1) * 100, 0), ROUND(-100 / (dec - 1), 0) ) ) ), "") | O20: ='First 5 Innings'!S15 -> 0 | P20: =IFERROR( _xlfn.LET( _xlpm.prob, 'First 5 Innings'!S15, _xlpm.dec, 1 / _xlpm.prob, IF(ABS(_xlpm.prob - 0.5) < 0.0001, 100, IF(_xlpm.dec >= 2, ROUND((_xlpm.dec - 1) * 100, 0), ROUND(-100 / (_xlpm.dec - 1), 0) ) ) ), "") | Q20: =IFERROR(1/'First 5 Innings'!AD15,"") | R20: =IFERROR( _xludf.LET( prob, Q20, dec, 1 / prob, IF(ABS(prob - 0.5) < 0.0001, 100, IF(dec >= 2, ROUND((dec - 1) * 100, 0), ROUND(-100 / (dec - 1), 0) ) ) ), "") | S20: =IFERROR(1/'First 5 Innings'!AE15,"") | T20: =IFERROR( _xludf.LET( prob, S20, dec, 1 / prob, IF(ABS(prob - 0.5) < 0.0001, 100, IF(dec >= 2, ROUND((dec - 1) * 100, 0), ROUND(-100 / (dec - 1), 0) ) ) ), "") | U20: =IF(C20="","", 'First 5 Innings'!T15) -> 10 | V20: =IF(C20="","", 'First 5 Innings'!AJ15) -> 10 | W20: =IF(C20="","", 'First 5 Innings'!AK15) -> 10 | X20: =IF( OR(D20="Average", D20="", D21=""), "", IF(AND(U20 >= $E$7, U20 <= 9.99), C20 & " f5 " & ROUND(P20, 0) & " " & 'First 5 Innings'!Q15, "" ) ) | Y20: {=IF( OR(D20="Average", D20="", D21=""), "", _xludf.TEXTJOIN(CHAR(10), TRUE, IF(AND(V20 >= $F$7, V20 <= 9.99), _xludf.XLOOKUP('First 5 Innings'!D15, Validations!$E$2:$E$31, Validations!$H$2:$H$31) & " " & 'First 5 Innings'!$AJ$4 & " " & IF('First 5 Innings'!AD15 >= 2, ROUND(('First 5 Innings'!AD15 - 1) * 100, 0), ROUND(-100 / ('First 5 Innings'!AD15 - 1), 0) ) & " " & 'First 5 Innings'!AL15, "" ), IF(AND(W20 >= $F$7, W20 <= 9.99), _xludf.XLOOKUP('First 5 Innings'!D15, Validations!$E$2:$E$31, Validations!$H$2:$H$31) & " " & 'First 5 Innings'!$AK$4 & " " & IF('First 5 Innings'!AE15 >= 2, ROUND(('First 5 Innings'!AE15 - 1) * 100, 0), ROUND(-100 / ('First 5 Innings'!AE15 - 1), 0) ) & " " & 'First 5 Innings'!AM15, "" ) ) )} -> #NAME? | Z20: =IF('First 5 Innings'!W15<2, -100/('First 5 Innings'!W15-1), ('First 5 Innings'!W15-1)*100) -> -133.72159 | AA20: =IF('First 5 Innings'!AN15<2, -100/('First 5 Innings'!AN15-1), ('First 5 Innings'!AN15-1)*100) -> -315.17353 | AB20: =IF('First 5 Innings'!AO15<2, -100/('First 5 Innings'!AO15-1), ('First 5 Innings'!AO15-1)*100) -> 109.5505
C21: =IFERROR(_xlfn.XLOOKUP('First 5 Innings'!D16,Validations!$E$2:$E$31,Validations!$H$2:$H$31),"") -> Cincinnati Reds | D21: =IFERROR('First 5 Innings'!B16,"") -> Brady Singer | E21: ='First 5 Innings'!C16 -> R | F21: {=IFERROR(_xlfn.XLOOKUP(D21,'Starting Pitchers'!$B$4:$B1007,'Starting Pitchers'!$Z$4:$Z1007),"")} -> 43 | G21: {=IFERROR(_xludf.XLOOKUP(D21,'Starting Pitchers'!$B$4:$B1007,'Starting Pitchers'!#REF!),"")} | H21: =IF('First 5 Innings'!G16=0,"",'First 5 Innings'!G16) -> 2.1072284 | I21: =IF(C21="","", 'First 5 Innings'!H16) -> 0.38507353 | J21: =IF(C21="","", _xlfn.LET( _xlpm.prob, 'First 5 Innings'!H16, _xlpm.dec, 1 / _xlpm.prob, IF(ABS(_xlpm.prob - 0.5) < 0.0001, 100, IF(_xlpm.dec >= 2, ROUND((_xlpm.dec - 1) * 100, 0), ROUND(-100 / (_xlpm.dec - 1), 0) ) ) )) -> 160 | K21: =IFERROR('First 5 Innings'!AH16,"") -> 0.47050925 | L21: =IFERROR( _xlfn.LET( _xlpm.prob, K21, _xlpm.dec, 1 / _xlpm.prob, IF(ABS(_xlpm.prob - 0.5) < 0.0001, 100, IF(_xlpm.dec >= 2, ROUND((_xlpm.dec - 1) * 100, 0), ROUND(-100 / (_xlpm.dec - 1), 0) ) ) ), "") -> 113 | M21: =IFERROR('First 5 Innings'!AI16,"") -> 0.29269051 | N21: =IFERROR( _xludf.LET( prob, M21, dec, 1 / prob, IF(ABS(prob - 0.5) < 0.0001, 100, IF(dec >= 2, ROUND((dec - 1) * 100, 0), ROUND(-100 / (dec - 1), 0) ) ) ), "") | O21: ='First 5 Innings'!S16 -> 0 | P21: =IFERROR( _xlfn.LET( _xlpm.prob, 'First 5 Innings'!S16, _xlpm.dec, 1 / _xlpm.prob, IF(ABS(_xlpm.prob - 0.5) < 0.0001, 100, IF(_xlpm.dec >= 2, ROUND((_xlpm.dec - 1) * 100, 0), ROUND(-100 / (_xlpm.dec - 1), 0) ) ) ), "") | Q21: =IFERROR(1/'First 5 Innings'!AD16,"") | R21: =IFERROR( _xludf.LET( prob, Q21, dec, 1 / prob, IF(ABS(prob - 0.5) < 0.0001, 100, IF(dec >= 2, ROUND((dec - 1) * 100, 0), ROUND(-100 / (dec - 1), 0) ) ) ), "") | S21: =IFERROR(1/'First 5 Innings'!AE16,"") | T21: =IFERROR( _xludf.LET( prob, S21, dec, 1 / prob, IF(ABS(prob - 0.5) < 0.0001, 100, IF(dec >= 2, ROUND((dec - 1) * 100, 0), ROUND(-100 / (dec - 1), 0) ) ) ), "") | U21: =IF(C21="","", 'First 5 Innings'!T16) -> 10 | V21: =IF(C21="","", 'First 5 Innings'!AJ16) -> 10 | W21: =IF(C21="","", 'First 5 Innings'!AK16) -> 10 | X21: =IF( OR(D21="Average", D21="", D22=""), "", IF(AND(U21 >= $E$7, U21 <= 9.99), C21 & " f5 " & ROUND(P21, 0) & " " & 'First 5 Innings'!Q16, "" ) ) | Y21: {=IF( OR(D21="Average", D21="", D22=""), "", _xludf.TEXTJOIN(CHAR(10), TRUE, IF(AND(V21 >= $F$7, V21 <= 9.99), _xludf.XLOOKUP('First 5 Innings'!D16, Validations!$E$2:$E$31, Validations!$H$2:$H$31) & " " & 'First 5 Innings'!$AJ$4 & " " & IF('First 5 Innings'!AD16 >= 2, ROUND(('First 5 Innings'!AD16 - 1) * 100, 0), ROUND(-100 / ('First 5 Innings'!AD16 - 1), 0) ) & " " & 'First 5 Innings'!AL16, "" ), IF(AND(W21 >= $F$7, W21 <= 9.99), _xludf.XLOOKUP('First 5 Innings'!D16, Validations!$E$2:$E$31, Validations!$H$2:$H$31) & " " & 'First 5 Innings'!$AK$4 & " " & IF('First 5 Innings'!AE16 >= 2, ROUND(('First 5 Innings'!AE16 - 1) * 100, 0), ROUND(-100 / ('First 5 Innings'!AE16 - 1), 0) ) & " " & 'First 5 Innings'!AM16, "" ) ) )} -> #NAME? | Z21: =IF('First 5 Innings'!W16<2, -100/('First 5 Innings'!W16-1), ('First 5 Innings'!W16-1)*100) -> 215.70802 | AA21: =IF('First 5 Innings'!AN16<2, -100/('First 5 Innings'!AN16-1), ('First 5 Innings'!AN16-1)*100) -> 115.91904 | AB21: =IF('First 5 Innings'!AO16<2, -100/('First 5 Innings'!AO16-1), ('First 5 Innings'!AO16-1)*100) -> 367.07022
B22: 7 | C22: =IFERROR(_xlfn.XLOOKUP('First 5 Innings'!D17,Validations!$E$2:$E$31,Validations!$H$2:$H$31),"") -> Pittsburgh Pirates | D22: =IFERROR('First 5 Innings'!B17,"") -> Mitch Keller | E22: ='First 5 Innings'!C17 -> R | F22: {=IFERROR(_xlfn.XLOOKUP(D22,'Starting Pitchers'!$B$4:$B1007,'Starting Pitchers'!$Z$4:$Z1007),"")} -> 140 | G22: {=IFERROR(_xludf.XLOOKUP(D22,'Starting Pitchers'!$B$4:$B1007,'Starting Pitchers'!#REF!),"")} | H22: =IF('First 5 Innings'!G17=0,"",'First 5 Innings'!G17) -> 2.6219046 | I22: =IF(C22="","", 'First 5 Innings'!H17) -> 0.75190149 | J22: =IF(C22="","", _xlfn.LET( _xlpm.prob, 'First 5 Innings'!H17, _xlpm.dec, 1 / _xlpm.prob, IF(ABS(_xlpm.prob - 0.5) < 0.0001, 100, IF(_xlpm.dec >= 2, ROUND((_xlpm.dec - 1) * 100, 0), ROUND(-100 / (_xlpm.dec - 1), 0) ) ) )) -> -303 | K22: =IFERROR('First 5 Innings'!AH17,"") -> 0.83065963 | L22: =IFERROR( _xlfn.LET( _xlpm.prob, K22, _xlpm.dec, 1 / _xlpm.prob, IF(ABS(_xlpm.prob - 0.5) < 0.0001, 100, IF(_xlpm.dec >= 2, ROUND((_xlpm.dec - 1) * 100, 0), ROUND(-100 / (_xlpm.dec - 1), 0) ) ) ), "") -> -491 | M22: =IFERROR('First 5 Innings'!AI17,"") -> 0.65901675 | N22: =IFERROR( _xludf.LET( prob, M22, dec, 1 / prob, IF(ABS(prob - 0.5) < 0.0001, 100, IF(dec >= 2, ROUND((dec - 1) * 100, 0), ROUND(-100 / (dec - 1), 0) ) ) ), "") | O22: ='First 5 Innings'!S17 -> 0 | P22: =IFERROR( _xlfn.LET( _xlpm.prob, 'First 5 Innings'!S17, _xlpm.dec, 1 / _xlpm.prob, IF(ABS(_xlpm.prob - 0.5) < 0.0001, 100, IF(_xlpm.dec >= 2, ROUND((_xlpm.dec - 1) * 100, 0), ROUND(-100 / (_xlpm.dec - 1), 0) ) ) ), "") | Q22: =IFERROR(1/'First 5 Innings'!AD17,"") | R22: =IFERROR( _xludf.LET( prob, Q22, dec, 1 / prob, IF(ABS(prob - 0.5) < 0.0001, 100, IF(dec >= 2, ROUND((dec - 1) * 100, 0), ROUND(-100 / (dec - 1), 0) ) ) ), "") | S22: =IFERROR(1/'First 5 Innings'!AE17,"") | T22: =IFERROR( _xludf.LET( prob, S22, dec, 1 / prob, IF(ABS(prob - 0.5) < 0.0001, 100, IF(dec >= 2, ROUND((dec - 1) * 100, 0), ROUND(-100 / (dec - 1), 0) ) ) ), "") | U22: =IF(C22="","", 'First 5 Innings'!T17) -> 10 | V22: =IF(C22="","", 'First 5 Innings'!AJ17) -> 10 | W22: =IF(C22="","", 'First 5 Innings'!AK17) -> 10 | X22: =IF( OR(D22="Average", D22="", D23=""), "", IF(AND(U22 >= $E$7, U22 <= 9.99), C22 & " f5 " & ROUND(P22, 0) & " " & 'First 5 Innings'!Q17, "" ) ) | Y22: {=IF( OR(D22="Average", D22="", D23=""), "", _xludf.TEXTJOIN(CHAR(10), TRUE, IF(AND(V22 >= $F$7, V22 <= 9.99), _xludf.XLOOKUP('First 5 Innings'!D17, Validations!$E$2:$E$31, Validations!$H$2:$H$31) & " " & 'First 5 Innings'!$AJ$4 & " " & IF('First 5 Innings'!AD17 >= 2, ROUND(('First 5 Innings'!AD17 - 1) * 100, 0), ROUND(-100 / ('First 5 Innings'!AD17 - 1), 0) ) & " " & 'First 5 Innings'!AL17, "" ), IF(AND(W22 >= $F$7, W22 <= 9.99), _xludf.XLOOKUP('First 5 Innings'!D17, Validations!$E$2:$E$31, Validations!$H$2:$H$31) & " " & 'First 5 Innings'!$AK$4 & " " & IF('First 5 Innings'!AE17 >= 2, ROUND(('First 5 Innings'!AE17 - 1) * 100, 0), ROUND(-100 / ('First 5 Innings'!AE17 - 1), 0) ) & " " & 'First 5 Innings'!AM17, "" ) ) )} -> #NAME? | Z22: =IF('First 5 Innings'!W17<2, -100/('First 5 Innings'!W17-1), ('First 5 Innings'!W17-1)*100) -> -262.75913 | AA22: =IF('First 5 Innings'!AN17<2, -100/('First 5 Innings'!AN17-1), ('First 5 Innings'!AN17-1)*100) -> -1053.7291 | AB22: =IF('First 5 Innings'!AO17<2, -100/('First 5 Innings'!AO17-1), ('First 5 Innings'!AO17-1)*100) -> -163.94258
C23: =IFERROR(_xlfn.XLOOKUP('First 5 Innings'!D18,Validations!$E$2:$E$31,Validations!$H$2:$H$31),"") -> New York Mets | D23: =IFERROR('First 5 Innings'!B18,"") -> David Peterson | E23: ='First 5 Innings'!C18 -> L | F23: {=IFERROR(_xlfn.XLOOKUP(D23,'Starting Pitchers'!$B$4:$B1007,'Starting Pitchers'!$Z$4:$Z1007),"")} -> 139 | G23: {=IFERROR(_xludf.XLOOKUP(D23,'Starting Pitchers'!$B$4:$B1007,'Starting Pitchers'!#REF!),"")} | H23: =IF('First 5 Innings'!G18=0,"",'First 5 Innings'!G18) -> 1.2917356 | I23: =IF(C23="","", 'First 5 Innings'!H18) -> 0.24809851 | J23: =IF(C23="","", _xlfn.LET( _xlpm.prob, 'First 5 Innings'!H18, _xlpm.dec, 1 / _xlpm.prob, IF(ABS(_xlpm.prob - 0.5) < 0.0001, 100, IF(_xlpm.dec >= 2, ROUND((_xlpm.dec - 1) * 100, 0), ROUND(-100 / (_xlpm.dec - 1), 0) ) ) )) -> 303 | K23: =IFERROR('First 5 Innings'!AH18,"") -> 0.34098325 | L23: =IFERROR( _xlfn.LET( _xlpm.prob, K23, _xlpm.dec, 1 / _xlpm.prob, IF(ABS(_xlpm.prob - 0.5) < 0.0001, 100, IF(_xlpm.dec >= 2, ROUND((_xlpm.dec - 1) * 100, 0), ROUND(-100 / (_xlpm.dec - 1), 0) ) ) ), "") -> 193 | M23: =IFERROR('First 5 Innings'!AI18,"") -> 0.16934037 | N23: =IFERROR( _xludf.LET( prob, M23, dec, 1 / prob, IF(ABS(prob - 0.5) < 0.0001, 100, IF(dec >= 2, ROUND((dec - 1) * 100, 0), ROUND(-100 / (dec - 1), 0) ) ) ), "") | O23: ='First 5 Innings'!S18 -> 0 | P23: =IFERROR( _xlfn.LET( _xlpm.prob, 'First 5 Innings'!S18, _xlpm.dec, 1 / _xlpm.prob, IF(ABS(_xlpm.prob - 0.5) < 0.0001, 100, IF(_xlpm.dec >= 2, ROUND((_xlpm.dec - 1) * 100, 0), ROUND(-100 / (_xlpm.dec - 1), 0) ) ) ), "") | Q23: =IFERROR(1/'First 5 Innings'!AD18,"") | R23: =IFERROR( _xludf.LET( prob, Q23, dec, 1 / prob, IF(ABS(prob - 0.5) < 0.0001, 100, IF(dec >= 2, ROUND((dec - 1) * 100, 0), ROUND(-100 / (dec - 1), 0) ) ) ), "") | S23: =IFERROR(1/'First 5 Innings'!AE18,"") | T23: =IFERROR( _xludf.LET( prob, S23, dec, 1 / prob, IF(ABS(prob - 0.5) < 0.0001, 100, IF(dec >= 2, ROUND((dec - 1) * 100, 0), ROUND(-100 / (dec - 1), 0) ) ) ), "") | U23: =IF(C23="","", 'First 5 Innings'!T18) -> 10 | V23: =IF(C23="","", 'First 5 Innings'!AJ18) -> 10 | W23: =IF(C23="","", 'First 5 Innings'!AK18) -> 10 | X23: =IF( OR(D23="Average", D23="", D24=""), "", IF(AND(U23 >= $E$7, U23 <= 9.99), C23 & " f5 " & ROUND(P23, 0) & " " & 'First 5 Innings'!Q18, "" ) ) | Y23: {=IF( OR(D23="Average", D23="", D24=""), "", _xludf.TEXTJOIN(CHAR(10), TRUE, IF(AND(V23 >= $F$7, V23 <= 9.99), _xludf.XLOOKUP('First 5 Innings'!D18, Validations!$E$2:$E$31, Validations!$H$2:$H$31) & " " & 'First 5 Innings'!$AJ$4 & " " & IF('First 5 Innings'!AD18 >= 2, ROUND(('First 5 Innings'!AD18 - 1) * 100, 0), ROUND(-100 / ('First 5 Innings'!AD18 - 1), 0) ) & " " & 'First 5 Innings'!AL18, "" ), IF(AND(W23 >= $F$7, W23 <= 9.99), _xludf.XLOOKUP('First 5 Innings'!D18, Validations!$E$2:$E$31, Validations!$H$2:$H$31) & " " & 'First 5 Innings'!$AK$4 & " " & IF('First 5 Innings'!AE18 >= 2, ROUND(('First 5 Innings'!AE18 - 1) * 100, 0), ROUND(-100 / ('First 5 Innings'!AE18 - 1), 0) ) & " " & 'First 5 Innings'!AM18, "" ) ) )} -> #NAME? | Z23: =IF('First 5 Innings'!W18<2, -100/('First 5 Innings'!W18-1), ('First 5 Innings'!W18-1)*100) -> 507.70362 | AA23: =IF('First 5 Innings'!AN18<2, -100/('First 5 Innings'!AN18-1), ('First 5 Innings'!AN18-1)*100) -> 231.97328 | AB23: =IF('First 5 Innings'!AO18<2, -100/('First 5 Innings'!AO18-1), ('First 5 Innings'!AO18-1)*100) -> 1197.9452
B24: 8 | C24: =IFERROR(_xlfn.XLOOKUP('First 5 Innings'!D19,Validations!$E$2:$E$31,Validations!$H$2:$H$31),"") -> Colorado Rockies | D24: =IFERROR('First 5 Innings'!B19,"") -> Michael Lorenzen | E24: ='First 5 Innings'!C19 -> R | F24: {=IFERROR(_xlfn.XLOOKUP(D24,'Starting Pitchers'!$B$4:$B1007,'Starting Pitchers'!$Z$4:$Z1007),"")} -> 135 | G24: {=IFERROR(_xludf.XLOOKUP(D24,'Starting Pitchers'!$B$4:$B1007,'Starting Pitchers'!#REF!),"")} | H24: =IF('First 5 Innings'!G19=0,"",'First 5 Innings'!G19) -> 2.0217493 | I24: =IF(C24="","", 'First 5 Innings'!H19) -> 0.52756979 | J24: =IF(C24="","", _xlfn.LET( _xlpm.prob, 'First 5 Innings'!H19, _xlpm.dec, 1 / _xlpm.prob, IF(ABS(_xlpm.prob - 0.5) < 0.0001, 100, IF(_xlpm.dec >= 2, ROUND((_xlpm.dec - 1) * 100, 0), ROUND(-100 / (_xlpm.dec - 1), 0) ) ) )) -> -112 | K24: =IFERROR('First 5 Innings'!AH19,"") -> 0.63129076 | L24: =IFERROR( _xlfn.LET( _xlpm.prob, K24, _xlpm.dec, 1 / _xlpm.prob, IF(ABS(_xlpm.prob - 0.5) < 0.0001, 100, IF(_xlpm.dec >= 2, ROUND((_xlpm.dec - 1) * 100, 0), ROUND(-100 / (_xlpm.dec - 1), 0) ) ) ), "") -> -171 | M24: =IFERROR('First 5 Innings'!AI19,"") -> 0.42203166 | N24: =IFERROR( _xludf.LET( prob, M24, dec, 1 / prob, IF(ABS(prob - 0.5) < 0.0001, 100, IF(dec >= 2, ROUND((dec - 1) * 100, 0), ROUND(-100 / (dec - 1), 0) ) ) ), "") | O24: ='First 5 Innings'!S19 -> 0 | P24: =IFERROR( _xlfn.LET( _xlpm.prob, 'First 5 Innings'!S19, _xlpm.dec, 1 / _xlpm.prob, IF(ABS(_xlpm.prob - 0.5) < 0.0001, 100, IF(_xlpm.dec >= 2, ROUND((_xlpm.dec - 1) * 100, 0), ROUND(-100 / (_xlpm.dec - 1), 0) ) ) ), "") | Q24: =IFERROR(1/'First 5 Innings'!AD19,"") | R24: =IFERROR( _xludf.LET( prob, Q24, dec, 1 / prob, IF(ABS(prob - 0.5) < 0.0001, 100, IF(dec >= 2, ROUND((dec - 1) * 100, 0), ROUND(-100 / (dec - 1), 0) ) ) ), "") | S24: =IFERROR(1/'First 5 Innings'!AE19,"") | T24: =IFERROR( _xludf.LET( prob, S24, dec, 1 / prob, IF(ABS(prob - 0.5) < 0.0001, 100, IF(dec >= 2, ROUND((dec - 1) * 100, 0), ROUND(-100 / (dec - 1), 0) ) ) ), "") | U24: =IF(C24="","", 'First 5 Innings'!T19) -> 10 | V24: =IF(C24="","", 'First 5 Innings'!AJ19) -> 10 | W24: =IF(C24="","", 'First 5 Innings'!AK19) -> 10 | X24: =IF( OR(D24="Average", D24="", D25=""), "", IF(AND(U24 >= $E$7, U24 <= 9.99), C24 & " f5 " & ROUND(P24, 0) & " " & 'First 5 Innings'!Q19, "" ) ) | Y24: {=IF( OR(D24="Average", D24="", D25=""), "", _xludf.TEXTJOIN(CHAR(10), TRUE, IF(AND(V24 >= $F$7, V24 <= 9.99), _xludf.XLOOKUP('First 5 Innings'!D19, Validations!$E$2:$E$31, Validations!$H$2:$H$31) & " " & 'First 5 Innings'!$AJ$4 & " " & IF('First 5 Innings'!AD19 >= 2, ROUND(('First 5 Innings'!AD19 - 1) * 100, 0), ROUND(-100 / ('First 5 Innings'!AD19 - 1), 0) ) & " " & 'First 5 Innings'!AL19, "" ), IF(AND(W24 >= $F$7, W24 <= 9.99), _xludf.XLOOKUP('First 5 Innings'!D19, Validations!$E$2:$E$31, Validations!$H$2:$H$31) & " " & 'First 5 Innings'!$AK$4 & " " & IF('First 5 Innings'!AE19 >= 2, ROUND(('First 5 Innings'!AE19 - 1) * 100, 0), ROUND(-100 / ('First 5 Innings'!AE19 - 1), 0) ) & " " & 'First 5 Innings'!AM19, "" ) ) )} -> #NAME? | Z24: =IF('First 5 Innings'!W19<2, -100/('First 5 Innings'!W19-1), ('First 5 Innings'!W19-1)*100) -> 110.49195 | AA24: =IF('First 5 Innings'!AN19<2, -100/('First 5 Innings'!AN19-1), ('First 5 Innings'!AN19-1)*100) -> -197.71958 | AB24: =IF('First 5 Innings'!AO19<2, -100/('First 5 Innings'!AO19-1), ('First 5 Innings'!AO19-1)*100) -> 179.47563
C25: =IFERROR(_xlfn.XLOOKUP('First 5 Innings'!D20,Validations!$E$2:$E$31,Validations!$H$2:$H$31),"") -> Miami Marlins | D25: =IFERROR('First 5 Innings'!B20,"") -> Eury Pérez | E25: ='First 5 Innings'!C20 -> R | F25: {=IFERROR(_xlfn.XLOOKUP(D25,'Starting Pitchers'!$B$4:$B1007,'Starting Pitchers'!$Z$4:$Z1007),"")} -> 89 | G25: {=IFERROR(_xludf.XLOOKUP(D25,'Starting Pitchers'!$B$4:$B1007,'Starting Pitchers'!#REF!),"")} | H25: =IF('First 5 Innings'!G20=0,"",'First 5 Innings'!G20) -> 1.8849384 | I25: =IF(C25="","", 'First 5 Innings'!H20) -> 0.47243021 | J25: =IF(C25="","", _xlfn.LET( _xlpm.prob, 'First 5 Innings'!H20, _xlpm.dec, 1 / _xlpm.prob, IF(ABS(_xlpm.prob - 0.5) < 0.0001, 100, IF(_xlpm.dec >= 2, ROUND((_xlpm.dec - 1) * 100, 0), ROUND(-100 / (_xlpm.dec - 1), 0) ) ) )) -> 112 | K25: =IFERROR('First 5 Innings'!AH20,"") -> 0.57796834 | L25: =IFERROR( _xlfn.LET( _xlpm.prob, K25, _xlpm.dec, 1 / _xlpm.prob, IF(ABS(_xlpm.prob - 0.5) < 0.0001, 100, IF(_xlpm.dec >= 2, ROUND((_xlpm.dec - 1) * 100, 0), ROUND(-100 / (_xlpm.dec - 1), 0) ) ) ), "") -> -137 | M25: =IFERROR('First 5 Innings'!AI20,"") -> 0.36870924 | N25: =IFERROR( _xludf.LET( prob, M25, dec, 1 / prob, IF(ABS(prob - 0.5) < 0.0001, 100, IF(dec >= 2, ROUND((dec - 1) * 100, 0), ROUND(-100 / (dec - 1), 0) ) ) ), "") | O25: ='First 5 Innings'!S20 -> 0 | P25: =IFERROR( _xlfn.LET( _xlpm.prob, 'First 5 Innings'!S20, _xlpm.dec, 1 / _xlpm.prob, IF(ABS(_xlpm.prob - 0.5) < 0.0001, 100, IF(_xlpm.dec >= 2, ROUND((_xlpm.dec - 1) * 100, 0), ROUND(-100 / (_xlpm.dec - 1), 0) ) ) ), "") | Q25: =IFERROR(1/'First 5 Innings'!AD20,"") | R25: =IFERROR( _xludf.LET( prob, Q25, dec, 1 / prob, IF(ABS(prob - 0.5) < 0.0001, 100, IF(dec >= 2, ROUND((dec - 1) * 100, 0), ROUND(-100 / (dec - 1), 0) ) ) ), "") | S25: =IFERROR(1/'First 5 Innings'!AE20,"") | T25: =IFERROR( _xludf.LET( prob, S25, dec, 1 / prob, IF(ABS(prob - 0.5) < 0.0001, 100, IF(dec >= 2, ROUND((dec - 1) * 100, 0), ROUND(-100 / (dec - 1), 0) ) ) ), "") | U25: =IF(C25="","", 'First 5 Innings'!T20) -> 10 | V25: =IF(C25="","", 'First 5 Innings'!AJ20) -> 10 | W25: =IF(C25="","", 'First 5 Innings'!AK20) -> 10 | X25: =IF( OR(D25="Average", D25="", D26=""), "", IF(AND(U25 >= $E$7, U25 <= 9.99), C25 & " f5 " & ROUND(P25, 0) & " " & 'First 5 Innings'!Q20, "" ) ) | Y25: {=IF( OR(D25="Average", D25="", D26=""), "", _xludf.TEXTJOIN(CHAR(10), TRUE, IF(AND(V25 >= $F$7, V25 <= 9.99), _xludf.XLOOKUP('First 5 Innings'!D20, Validations!$E$2:$E$31, Validations!$H$2:$H$31) & " " & 'First 5 Innings'!$AJ$4 & " " & IF('First 5 Innings'!AD20 >= 2, ROUND(('First 5 Innings'!AD20 - 1) * 100, 0), ROUND(-100 / ('First 5 Innings'!AD20 - 1), 0) ) & " " & 'First 5 Innings'!AL20, "" ), IF(AND(W25 >= $F$7, W25 <= 9.99), _xludf.XLOOKUP('First 5 Innings'!D20, Validations!$E$2:$E$31, Validations!$H$2:$H$31) & " " & 'First 5 Innings'!$AK$4 & " " & IF('First 5 Innings'!AE20 >= 2, ROUND(('First 5 Innings'!AE20 - 1) * 100, 0), ROUND(-100 / ('First 5 Innings'!AE20 - 1), 0) ) & " " & 'First 5 Innings'!AM20, "" ) ) )} -> #NAME? | Z25: =IF('First 5 Innings'!W20<2, -100/('First 5 Innings'!W20-1), ('First 5 Innings'!W20-1)*100) -> 141.65602 | AA25: =IF('First 5 Innings'!AN20<2, -100/('First 5 Innings'!AN20-1), ('First 5 Innings'!AN20-1)*100) -> -148.42278 | AB25: =IF('First 5 Innings'!AO20<2, -100/('First 5 Innings'!AO20-1), ('First 5 Innings'!AO20-1)*100) -> 234.93452
